Workbook

Sheet Home
B2: Lunes 2/9 | L2: Calculo Suscriptores | O2: Mes | P2: Subs | Q2: Crecimiento | R2: Promedio
B3: Programa | C3: Media real | D3: Media Total | E3: Gastos | L3: Subs actual | M3: 59400 | O3: Enero | P3: 23700
B4: RUMIS | C4: ='02'!F3 -> 3432.3448 | D4: ='02'!G3 -> 13259.931 | E4: ='02'!H3 -> 387.61 | L4: Objetivo | M4: 100000 | O4: Febrero | P4: 29400 | Q4: =P4-P3 -> 5700
B5: CIRCUITO | C5: ='02'!F41 -> 4997.3704 | D5: ='02'!G41 -> 11578.852 | E5: ='02'!H41 -> 279.14 | L5: Faltan | M5: =M4-M3 -> 40600 | O5: Marzo | P5: 33100 | Q5: =P5-P4 -> 3700
B6: MADRES | C6: ='02'!F71 -> 1944.5556 | D6: ='02'!G71 -> 7203.8148 | E6: ='02'!H71 -> 191.55 | L6: Promedio organico / mes | M6: =R6 -> 5063.8571 | O6: Abril | P6: 40600 | Q6: =P6-P5 -> 7500 | R6: =AVERAGE(Q4:Q10) -> 5063.8571
E7: =SUM(E4:E6) -> 858.3 | F7: Total del dia | L7: Meses faltantes | M7: 4 | O7: Mayo | P7: 46000 | Q7: =P7-P6 -> 5400
L8: Estimacion organica | M8: =M6*M7 -> 20255.429 | O8: Junio | P8: 48800 | Q8: =P8-P7 -> 2800
L9: Faltante para objetivo | M9: =M5-M8 -> 20344.571 | O9: Julio | P9: 51900 | Q9: =P9-P8 -> 3100
B10: Martes 3/9 | L10: Costo faltantes | M10: 1300 | O10: Agosto | P10: 59147 | Q10: =P10-P9 -> 7247
B11: Programa | C11: Media real | D11: Media Total | E11: Gastos | L11: Costo por mes | M11: =M10/M7 -> 325
B12: RUMIS | C12: ='03'!F3 -> 3752.8571 | D12: ='03'!G3 -> 14824.286 | E12: ='03'!H3 -> 495.58
B13: CIRCUITO | C13: ='03'!F34 -> 3024.04 | D13: ='03'!G34 -> 9764.04 | E13: ='03'!H34 -> 45.205
E14: =SUM(E12:E13) -> 540.785 | F14: Total del dia
B17: Miercoles 4/9
B18: Programa | C18: Media real | D18: Media Total | E18: Gastos
B19: RUMIS | C19: ='04'!#REF! -> #REF! | D19: ='04'!#REF! -> #REF! | E19: ='04'!#REF! -> #REF!
B20: CIRCUITO | C20: ='04'!#REF! -> #REF! | D20: ='04'!#REF! -> #REF! | E20: ='04'!#REF! -> #REF!
E21: =SUM(E19:E20) -> #REF! | F21: Total del dia

Sheet Hoja1
A3: Etiquetas de fila | B3: Suma de Cant
A4: 13:30 | B4: -1384
A5: 13:35 | B5: 1908
A6: 13:40 | B6: 402
A7: 13:45 | B7: 1149
A8: 13:50 | B8: 357
A9: 13:55 | B9: -104
A10: 14:00 | B10: -276 | D10: Fecha | E10: Cant | F10: hora
A11: 14:05 | B11: 52 | D11: 45539 | E11: 116 | F11: 13:30
A12: 14:10 | B12: -781 | D12: 45539 | E12: -420 | F12: 13:30
A13: 14:15 | B13: 283 | D13: 45539 | E13: -420 | F13: 13:30 | K13: 13:30 | L13: -1384
A14: 14:20 | B14: 1121 | D14: 45539 | E14: -420 | F14: 13:30 | K14: 13:35 | L14: 1908
A15: 14:25 | B15: -682 | D15: 45539 | E15: -240 | F15: 13:30 | K15: 13:40 | L15: 402
A16: 14:30 | B16: -1722 | D16: 45539 | E16: 636 | F16: 13:35 | K16: 13:45 | L16: 1149
A17: 14:35 | B17: -866 | D17: 45539 | E17: 636 | F17: 13:35 | K17: 13:50 | L17: 357
A18: 14:40 | B18: -19 | D18: 45539 | E18: 636 | F18: 13:35 | K18: 13:55 | L18: -104
A19: 14:45 | B19: 623 | D19: 45539 | E19: 77 | F19: 13:40 | K19: 14:00 | L19: -276
A20: 14:55 | B20: -2458 | D20: 45539 | E20: 325 | F20: 13:40 | K20: 14:05 | L20: 52
A21: 15:05 | B21: -3319 | D21: 45539 | E21: 159 | F21: 13:45 | K21: 14:10 | L21: -781
A22: 15:10 | B22: -6092 | D22: 45539 | E22: 248 | F22: 13:45 | K22: 14:15 | L22: 283
A23: 15:20 | B23: -3739 | D23: 45539 | E23: 248 | F23: 13:45 | K23: 14:20 | L23: 1121
A24: 15:30 | B24: 2496 | D24: 45539 | E24: 248 | F24: 13:45 | K24: 14:25 | L24: -682
... A33: Total general | B33: -15089 | D33: 45539 | E33: -92 | F33: 14:00 | K33: 15:30 | L33: 2496
D34: 45539 | E34: 20 | F34: 14:05 | K34: 15:40 | L34: 297
D35: 45539 | E35: -9 | F35: 14:05 | K35: 15:45 | L35: 73
D36: 45539 | E36: -9 | F36: 14:05 | K36: 15:55 | L36: -850
D37: 45539 | E37: 50 | F37: 14:05 | K37: 16:00 | L37: 80
D38: 45539 | E38: -212 | F38: 14:10 | K38: 16:10 | L38: 440
D39: 45539 | E39: -311 | F39: 14:10 | K39: 16:15 | L39: 73
D40: 45539 | E40: -258 | F40: 14:10 | K40: 16:25 | L40: -312
D41: 45539 | E41: 132 | F41: 14:15 | K41: 16:30 | L41: -1839
D42: 45539 | E42: 151 | F42: 14:15
D43: 45539 | E43: 341 | F43: 14:20
D44: 45539 | E44: 407 | F44: 14:20
D45: 45539 | E45: 373 | F45: 14:20
D46: 45539 | E46: -345 | F46: 14:25
D47: 45539 | E47: -337 | F47: 14:25
D48: 45539 | E48: -653 | F48: 14:30
D49: 45539 | E49: -333 | F49: 14:30
D50: 45539 | E50: -360 | F50: 14:30
...

Sheet 04
A1: RUMIS
A2: Hora | B2: Real | C2: Chimi | D2: Total
A3: 11:25 | B3: 5 | C3: 0 | D3: 5
A4: 11:30 | B4: 25 | C4: 0 | D4: 25
A5: 11:35 | B5: 49 | C5: 0 | D5: 49
A6: 11:40 | B6: 80 | C6: 0 | D6: 80
A7: 11:45 | B7: 121 | C7: 0 | D7: 121
A8: 11:50 | B8: 237 | C8: 500 | D8: 737
A9: 11:55 | B9: 572 | C9: 2000 | D9: 2572
A10: 12:00 | B10: 3017 | C10: 2000 | D10: 5017
A11: 12:05 | B11: 3908 | C11: 2000 | D11: 5908
A12: 12:10 | B12: 2201 | C12: 4000 | D12: 6201
A13: 12:15 | B13: 4600 | C13: 6500 | D13: 11100
A14: 12:20 | B14: 4848 | C14: 6500 | D14: 11348
... A39: 14:25 | B39: 8314 | C39: 9500 | D39: 17814
A41: CIRCUITO CERRADO
A42: Hora | B42: Real | C42: Chimi | D42: Total
A43: 0.60416667 | B43: 8079 | C43: 9500 | D43: 17579
A44: 14:35 | B44: 7957 | C44: 9500 | D44: 17457
A45: 14:40 | B45: 8007 | C45: 9500 | D45: 17507
A46: 14:45 | B46: 8079 | C46: 9500 | D46: 17579
A47: 14:50 | B47: 7980 | C47: 9500 | D47: 17480
A48: 14:55 | B48: 7234 | C48: 9500 | D48: 16734
A49: 15:00 | B49: 5393 | C49: 9500 | D49: 14893
A50: 15:05 | B50: 2672 | C50: 9500 | D50: 12172
A51: 15:10 | B51: 2538 | C51: 9500 | D51: 12038
A52: 15:15 | B52: 2648 | C52: 9500 | D52: 12148
A53: 15:20 | B53: 2704 | C53: 5000 | D53: 7704
A54: 15:25 | B54: 5087 | C54: 6000 | D54: 11087
A55: 15:30 | B55: 4125 | C55: 6000 | D55: 10125
... A68: 16:35 | B68: 2028 | C68: 6000 | D68: 8028
A70: MADRES 5G
A71: Hora | B71: Real | C71: Chimi | D71: Total
A72: 0.48263889 | B72: 8089 | C72: 9100 | D72: 17679

Sheet 03
A1: RUMIS
A2: Hora | B2: Real | C2: Chimi | D2: Total | F2: Media Real | G2: Media Total | H2: Gastos
A3: 0.47916667 | B3: =D3-C3 -> 21 | C3: 0 | D3: 21 | F3: =AVERAGE(B9:B29) -> 3752.8571 | G3: =AVERAGE(D9:D29) -> 14824.286 | H3: =CC!K22+CC!K21+CC!K20+CC!K19+CC!K18+CC!K17+CC!K16+(CC!K15/2)+CC!K14+CC!K13 -> 495.58
A4: 0.48263889 | B4: =D4-C4 -> 68 | C4: 0 | D4: 68
A5: 0.48611111 | B5: =D5-C5 -> 151 | C5: 500 | D5: 651
A6: 0.48958333 | B6: =D6-C6 -> 301 | C6: 1500 | D6: 1801
A7: 0.49305556 | B7: =D7-C7 -> 384 | C7: 1500 | D7: 1884
A8: 0.49652778 | B8: =D8-C8 -> 391 | C8: 1500 | D8: 1891
A9: 0.5 | B9: =D9-C9 -> 3232 | C9: 1500 | D9: 4732
A10: 0.50347222 | B10: =D10-C10 -> 3782 | C10: 1500 | D10: 5282
A11: 0.50694444 | B11: =D11-C11 -> 4005 | C11: 1500 | D11: 5505
A12: 0.51041667 | B12: =D12-C12 -> 3411 | C12: 4000 | D12: 7411
A13: 0.51388889 | B13: =D13-C13 -> 2369 | C13: 10500 | D13: 12869
A14: 0.51736111 | B14: =D14-C14 -> 2541 | C14: 10500 | D14: 13041
A15: 0.52083333 | B15: =D15-C15 -> 3885 | C15: 10500 | D15: 14385
... A29: 0.60069444 | B29: =D29-C29 -> 2778 | C29: 10500 | D29: 13278
A32: CIRCUITO CERRADO
A33: Hora | B33: Real | C33: Chimi | D33: Total | F33: Media Real | G33: Media Total | H33: Gastos
A34: 0.60416667 | B34: =D34-C34 -> 2417 | C34: 11600 | D34: 14017 | F34: =AVERAGE(B34:B58) -> 3024.04 | G34: =AVERAGE(D34:D58) -> 9764.04 | H34: =(CC!K46/2)+CC!K12+CC!K11 -> 45.205
A35: 0.60763889 | B35: =D35-C35 -> 2320 | C35: 11600 | D35: 13920
A36: 0.61111111 | B36: =D36-C36 -> 2327 | C36: 11600 | D36: 13927
A37: 0.61458333 | B37: =D37-C37 -> 2370 | C37: 11600 | D37: 13970
A38: 0.61805556 | B38: =D38-C38 -> 6215 | C38: 6600 | D38: 12815
A39: 0.62152778 | B39: =D39-C39 -> 6107 | C39: 6600 | D39: 12707
A40: 0.625 | B40: =D40-C40 -> 4961 | C40: 5100 | D40: 10061
A41: 0.62847222 | B41: =D41-C41 -> 4630 | C41: 5100 | D41: 9730
A42: 0.63194444 | B42: =D42-C42 -> 4623 | C42: 5100 | D42: 9723
A43: 0.63541667 | B43: =D43-C43 -> 4579 | C43: 5100 | D43: 9679
A44: 0.63888889 | B44: =D44-C44 -> 2790 | C44: 5100 | D44: 7890
A45: 0.64236111 | B45: =D45-C45 -> 2776 | C45: 5100 | D45: 7876
A46: 0.64583333 | B46: =D46-C46 -> 2742 | C46: 5100 | D46: 7842
... A58: 0.6875 | B58: =D58-C58 -> 1019 | C58: 6100 | D58: 7119

Sheet 02
A1: RUMIS
A2: Hora | B2: Real | C2: Chimi | D2: Total | F2: Media Real | G2: Media Total | H2: Gastos
A3: 11:35 | B3: =D3-C3 -> 71 | C3: 0 | D3: 71 | F3: =AVERAGE(B9:B37) -> 3432.3448 | G3: =AVERAGE(D9:D37) -> 13259.931 | H3: =CC!K38+(CC!K37/2)+CC!K36+CC!K35+CC!K34+CC!K33 -> 387.61
A4: 11:40 | B4: =D4-C4 -> 99 | C4: 0 | D4: 99
A5: 11:45 | B5: =D5-C5 -> 523 | C5: 2500 | D5: 3023
A6: 11:50 | B6: =D6-C6 -> 578 | C6: 2500 | D6: 3078
A7: 11:55 | B7: =D7-C7 -> 628 | C7: 2500 | D7: 3128
A8: 12:00 | B8: =D8-C8 -> 891 | C8: 2500 | D8: 3391
A9: 12:05 | B9: =D9-C9 -> 1956 | C9: 7500 | D9: 9456
A10: 12:10 | B10: =D10-C10 -> 2262 | C10: 7500 | D10: 9762
A11: 12:15 | B11: =D11-C11 -> 2815 | C11: 10000 | D11: 12815
A12: 12:20 | B12: =D12-C12 -> 2949 | C12: 10000 | D12: 12949
A13: 12:25 | B13: =D13-C13 -> 2946 | C13: 10000 | D13: 12946
A14: 12:30 | B14: =D14-C14 -> 3174 | C14: 10000 | D14: 13174
A15: 12:35 | B15: =D15-C15 -> 3223 | C15: 10000 | D15: 13223
... A37: 14:25 | B37: =D37-C37 -> 3819 | C37: 10000 | D37: 13819
A39: CIRCUITO CERRADO
A40: Hora | B40: Real | C40: Chimi | D40: Total | F40: Media Real | G40: Media Total | H40: Gastos
A41: 14:30 | B41: =D41-C41 -> 4299 | C41: 9600 | D41: 13899 | F41: =AVERAGE(B41:B67) -> 4997.3704 | G41: =AVERAGE(D41:D67) -> 11578.852 | H41: =(CC!K37/2)+CC!K32+CC!K31 -> 279.14
A42: 14:35 | B42: =D42-C42 -> 6134 | C42: 9600 | D42: 15734
A43: 14:40 | B43: =D43-C43 -> 6141 | C43: 9600 | D43: 15741
A44: 14:45 | B44: =D44-C44 -> 6122 | C44: 9600 | D44: 15722
A45: 14:50 | B45: =D45-C45 -> 5818 | C45: 7100 | D45: 12918
A46: 14:55 | B46: =D46-C46 -> 5571 | C46: 7100 | D46: 12671
A47: 15:00 | B47: =D47-C47 -> 5627 | C47: 7100 | D47: 12727
A48: 15:05 | B48: =D48-C48 -> 5604 | C48: 7100 | D48: 12704
A49: 15:10 | B49: =D49-C49 -> 5544 | C49: 7100 | D49: 12644
A50: 15:15 | B50: =D50-C50 -> 5516 | C50: 7100 | D50: 12616
A51: 15:20 | B51: =D51-C51 -> 2762 | C51: 7100 | D51: 9862
A52: 15:25 | B52: =D52-C52 -> 2714 | C52: 7100 | D52: 9814
A53: 15:30 | B53: =D53-C53 -> 2616 | C53: 7100 | D53: 9716
... A67: 16:40 | B67: =D67-C67 -> 4730 | C67: 4100 | D67: 8830
A69: MADRES 5G
A70: Hora | B70: Real | C70: Chimi | D70: Total | F70: Media Real | G70: Media Total | H70: Gastos
A71: 20:55 | B71: =D71-C71 -> 144 | C71: 2500 | D71: 2644 | F71: =AVERAGE(B71:B97) -> 1944.5556 | G71: =AVERAGE(D71:D97) -> 7203.8148 | H71: =CC!K30+CC!K29+CC!K28+CC!K27+CC!K26+CC!K25+CC!K24+CC!K23 -> 191.55
A72: 21:00 | B72: =D72-C72 -> 296 | C72: 2500 | D72: 2796
A73: 21:05 | B73: =D73-C73 -> 542 | C73: 2500 | D73: 3042
A74: 21:10 | B74: =D74-C74 -> 154 | C74: 3500 | D74: 3654
A75: 21:15 | B75: =D75-C75 -> 1843 | C75: 3500 | D75: 5343
A76: 21:20 | B76: =D76-C76 -> 987 | C76: 4500 | D76: 5487
...

Sheet CC
A2: 45532 | B2: 0.91636574 | C2: 10.00 | H2: Operation | I2: Date of payment | K2: Amount | L2: Residue
A3: 45533 | B3: 0.72994213 | C3: 175.00$ | D3: 175.33$ | H3: ID Order 9101597 | I3: 45539 | J3: 0.77096065 | K3: 3.13 | L3: 0.11
A4: 45534 | B4: 0.72680556 | C4: 280.00$ | D4: 282.83$ | H4: ID Order 9101595 | I4: 45539 | J4: 0.77037037 | K4: 389.5 | L4: 3.24
A5: 45534 | B5: 0.80773148 | C5: 50.00$ | D5: 50.39$ | H5: ID Order 9101554 | I5: 45539 | J5: 0.75967593 | K5: 3.32 | L5: 392.74
A6: 45537 | B6: 0.69532407 | C6: 625.00$ | D6: 643.14$ | H6: ID Order 9101552 | I6: 45539 | J6: 0.75877315 | K6: 138 | L6: 396.06
A7: 45537 | B7: 0.8672338 | C7: 200.00$ | D7: 202.19$ | H7: ID Order 9101523 | I7: 45539 | J7: 0.750625 | K7: 0.55 | L7: 534.06
A8: 45538 | B8: 0.14626157 | C8: 50.00$ | D8: 54.19$ | H8: ID Order 9101521 | I8: 45539 | J8: 0.75002315 | K8: 86.25 | L8: 534.61
A9: 45538 | B9: 0.7209375 | C9: 650.00$ | D9: 684.84$ | H9: ID Order 9101479 | I9: 45539 | J9: 0.74469907 | K9: 51.75 | L9: 620.86
A10: 45538 | B10: 0.87140046 | C10: 50.00$ | D10: 52.76$ | H10: ID Order 9101459 | I10: 45539 | J10: 0.74091435 | K10: 17.25 | L10: 672.61
A11: 45539 | B11: 0.70358796 | C11: 650.00$ | D11: 689.86$ | H11: ID Order 9097548 | I11: 45538 | J11: 0.90377315 | K11: 12.9 | L11: 39.86
A12: 45540 | B12: 0.70158565 | C12: 700.00$ | D12: 700.11$ | H12: ID Order 9097131 | I12: 45538 | J12: 0.85122685 | K12: 30.69 | L12: 2.76
H13: ID Order 9096635 | I13: 45538 | J13: 0.7894213 | K13: 9.6 | L13: 33.45
H14: ID Order 9096534 | I14: 45538 | J14: 0.77841435 | K14: 4.23 | L14: 43.05
H15: ID Order 9096429 | I15: 45538 | J15: 0.77077546 | K15: 311.6 | L15: 47.28
H16: ID Order 9096400 | I16: 45538 | J16: 0.76579861 | K16: 5.44 | L16: 358.88
H17: ID Order 9096391 | I17: 45538 | J17: 0.76373843 | K17: 139.5 | L17: 364.32
H18: ID Order 9096334 | I18: 45538 | J18: 0.75896991 | K18: 51.75 | L18: 503.82
H19: ID Order 9096255 | I19: 45538 | J19: 0.74753472 | K19: 86.25 | L19: 555.57
H20: ID Order 9096227 | I20: 45538 | J20: 0.7403588 | K20: 2.06 | L20: 641.82
H21: ID Order 9096223 | I21: 45538 | J21: 0.73951389 | K21: 34.5 | L21: 643.89
H22: ID Order 9096194 | I22: 45538 | J22: 0.73427083 | K22: 6.45 | L22: 678.39
H23: ID Order 9093594 | I23: 45538 | J23: 0.14706019 | K23: 19.35 | L23: 34.84
H24: ID Order 9093532 | I24: 45538 | J24: 0.14167824 | K24: 13.95 | L24: 4.19
... H47: ID Order 9067628 | I47: 45532 | J47: 0.91663194 | K47: 6.45 | L47: 3.55
